<?xml version="1.0" encoding="utf-8"?>
<!-- This URDF was automatically created by SolidWorks to URDF Exporter! Originally created by Stephen Brawner (brawner@gmail.com) 
     Commit Version: 1.6.0-4-g7f85cfe  Build Version: 1.6.7995.38578
     For more information, please see http://wiki.ros.org/sw_urdf_exporter -->
<robot
  name="ball_balancer">
  <link
    name="base_link">
    <inertial>
      <origin
        xyz="-0.000283424831778992 0.0148687672016035 0.00098764643898577"
        rpy="0 0 0" />
      <mass
        value="0.140328552667325" />
      <inertia
        ixx="0.000339607629485261"
        ixy="-6.49084497217985E-07"
        ixz="-2.8151634803952E-06"
        iyy="0.00059971311240308"
        iyz="9.87253552797209E-07"
        izz="0.000336206338172807" />
    </inertial>
    <visual>
      <origin
        xyz="0 0 0"
        rpy="0 0 0" />
      <geometry>
        <mesh
          filename="package://ball_balancer/meshes/base_link.STL" />
      </geometry>
      <material
        name="">
        <color
          rgba="0.792156862745098 0.819607843137255 0.933333333333333 1" />
      </material>
    </visual>
    <collision>
      <origin
        xyz="0 0 0"
        rpy="0 0 0" />
      <geometry>
        <mesh
          filename="package://ball_balancer/meshes/base_link.STL" />
      </geometry>
    </collision>
  </link>
  <joint
    name="servo_arm_3_joint"
    type="revolute">
    <origin
      xyz="-0.053279 0.03919 0.03755"
      rpy="0 0 -2.0944" />
    <parent
      link="base_link" />
    <child
      link="servo_arm_3_link" />
    <axis
      xyz="-1 0 0" />
    <limit
      lower="0"
      upper="1.57"
      effort="1.9"
      velocity="5.5" />
  </joint>
  <link
    name="servo_arm_1_link">
    <inertial>
      <origin
        xyz="3.6744E-05 0.014137 -7.6328E-17"
        rpy="0 0 0" />
      <mass
        value="0.0030998" />
      <inertia
        ixx="7.5306E-07"
        ixy="1.4683E-22"
        ixz="-6.7515E-25"
        iyy="5.9756E-08"
        iyz="-1.1724E-21"
        izz="7.0606E-07" />
    </inertial>
    <visual>
      <origin
        xyz="0 0 0"
        rpy="0 0 0" />
      <geometry>
        <mesh
          filename="package://ball_balancer/meshes/servo_arm_1_link.STL" />
      </geometry>
      <material
        name="">
        <color
          rgba="0.79216 0.81961 0.93333 1" />
      </material>
    </visual>
    <collision>
      <origin
        xyz="0 0 0"
        rpy="0 0 0" />
      <geometry>
        <mesh
          filename="package://ball_balancer/meshes/servo_arm_1_link.STL" />
      </geometry>
    </collision>
  </link>
  <joint
    name="servo_arm_1_joint"
    type="revolute">
    <origin
      xyz="-0.0073 -0.065736 0.03755"
      rpy="0 0 0" />
    <parent
      link="base_link" />
    <child
      link="servo_arm_1_link" />
    <axis
      xyz="-1 0 0" />
    <limit
      lower="0"
      upper="1.57"
      effort="1.9"
      velocity="5.5" />
  </joint>
  <link
    name="table_arm_1_link">
    <inertial>
      <origin
        xyz="0.00200323165118161 -0.030245588924881 -1.1886146417811E-08"
        rpy="0 0 0" />
      <mass
        value="0.00256322375311019" />
      <inertia
        ixx="2.5397647409349E-07"
        ixy="2.24719540974155E-08"
        ixz="3.50562172662121E-14"
        iyy="3.10173137802653E-08"
        iyz="-3.73742597115702E-13"
        izz="2.47421754391359E-07" />
    </inertial>
    <visual>
      <origin
        xyz="0 0 0"
        rpy="0 0 0" />
      <geometry>
        <mesh
          filename="package://ball_balancer/meshes/table_arm_1_link.STL" />
      </geometry>
      <material
        name="">
        <color
          rgba="0.792156862745098 0.819607843137255 0.933333333333333 1" />
      </material>
    </visual>
    <collision>
      <origin
        xyz="0 0 0"
        rpy="0 0 0" />
      <geometry>
        <mesh
          filename="package://ball_balancer/meshes/table_arm_1_link.STL" />
      </geometry>
    </collision>
  </link>
  <joint
    name="table_arm_1_joint"
    type="revolute">
    <origin
      xyz="0.00455 0.039365 0"
      rpy="-0.2618 0 0" />
    <parent
      link="servo_arm_1_link" />
    <child
      link="table_arm_1_link" />
    <axis
      xyz="1 0 0" />
    <limit
      lower="-1.57"
      upper="0"
      effort="1.9"
      velocity="5.5" />
  </joint>
  <link
    name="servo_arm_2_link">
    <inertial>
      <origin
        xyz="3.6744E-05 0.014137 -8.3267E-17"
        rpy="0 0 0" />
      <mass
        value="0.0030998" />
      <inertia
        ixx="7.5306E-07"
        ixy="2.1176E-22"
        ixz="1.409E-24"
        iyy="5.9756E-08"
        iyz="-1.2835E-21"
        izz="7.0606E-07" />
    </inertial>
    <visual>
      <origin
        xyz="0 0 0"
        rpy="0 0 0" />
      <geometry>
        <mesh
          filename="package://ball_balancer/meshes/servo_arm_2_link.STL" />
      </geometry>
      <material
        name="">
        <color
          rgba="0.79216 0.81961 0.93333 1" />
      </material>
    </visual>
    <collision>
      <origin
        xyz="0 0 0"
        rpy="0 0 0" />
      <geometry>
        <mesh
          filename="package://ball_balancer/meshes/servo_arm_2_link.STL" />
      </geometry>
    </collision>
  </link>
  <joint
    name="servo_arm_2_joint"
    type="revolute">
    <origin
      xyz="0.060579 0.026546 0.03755"
      rpy="0 0 2.0944" />
    <parent
      link="base_link" />
    <child
      link="servo_arm_2_link" />
    <axis
      xyz="-1 0 0" />
    <limit
      lower="0"
      upper="1.57"
      effort="1.9"
      velocity="5.5" />
  </joint>
  <link
    name="table_arm_2_link">
    <inertial>
      <origin
        xyz="0.0020032 -0.030246 -9.3098E-09"
        rpy="0 0 0" />
      <mass
        value="0.0025632" />
      <inertia
        ixx="2.5398E-07"
        ixy="2.2472E-08"
        ixz="4.9663E-14"
        iyy="3.1017E-08"
        iyz="-2.9652E-13"
        izz="2.4742E-07" />
    </inertial>
    <visual>
      <origin
        xyz="0 0 0"
        rpy="0 0 0" />
      <geometry>
        <mesh
          filename="package://ball_balancer/meshes/table_arm_2_link.STL" />
      </geometry>
      <material
        name="">
        <color
          rgba="0.79216 0.81961 0.93333 1" />
      </material>
    </visual>
    <collision>
      <origin
        xyz="0 0 0"
        rpy="0 0 0" />
      <geometry>
        <mesh
          filename="package://ball_balancer/meshes/table_arm_2_link.STL" />
      </geometry>
    </collision>
  </link>
  <joint
    name="table_arm_2_joint"
    type="revolute">
    <origin
      xyz="0.00455 0.039365 0"
      rpy="-0.27925 0 0" />
    <parent
      link="servo_arm_2_link" />
    <child
      link="table_arm_2_link" />
    <axis
      xyz="1 0 0" />
    <limit
      lower="-1.57"
      upper="0"
      effort="1.9"
      velocity="5.5" />
  </joint>
  <link
    name="servo_arm_3_link">
    <inertial>
      <origin
        xyz="0 0 0"
        rpy="0 0 0" />
      <mass
        value="0" />
      <inertia
        ixx="0"
        ixy="0"
        ixz="0"
        iyy="0"
        iyz="0"
        izz="0" />
    </inertial>
    <visual>
      <origin
        xyz="0 0 0"
        rpy="0 0 0" />
      <geometry>
        <mesh
          filename="package://ball_balancer/meshes/servo_arm_3_link.STL" />
      </geometry>
      <material
        name="">
        <color
          rgba="1 1 1 1" />
      </material>
    </visual>
    <collision>
      <origin
        xyz="0 0 0"
        rpy="0 0 0" />
      <geometry>
        <mesh
          filename="package://ball_balancer/meshes/servo_arm_3_link.STL" />
      </geometry>
    </collision>
  </link>
  <joint
    name="servo_arm_3_joint"
    type="revolute">
    <origin
      xyz="-0.053279 0.03919 0.03755"
      rpy="0 0 -2.0944" />
    <parent
      link="base_link" />
    <child
      link="servo_arm_3_link" />
    <axis
      xyz="-1 0 0" />
    <limit
      lower="0"
      upper="1.57"
      effort="1.9"
      velocity="5.5" />
  </joint>
  <link
    name="table_arm_3_link">
    <inertial>
      <origin
        xyz="0.00200321195554558 -0.0302455620616148 -1.03093975890867E-08"
        rpy="0 0 0" />
      <mass
        value="0.00256319746004798" />
      <inertia
        ixx="2.53973519433809E-07"
        ixy="2.24713070970576E-08"
        ixz="1.27314190246233E-13"
        iyy="3.10171931225823E-08"
        iyz="-3.13248110084386E-13"
        izz="2.47418505658137E-07" />
    </inertial>
    <visual>
      <origin
        xyz="0 0 0"
        rpy="0 0 0" />
      <geometry>
        <mesh
          filename="package://ball_balancer/meshes/table_arm_3_link.STL" />
      </geometry>
      <material
        name="">
        <color
          rgba="0.792156862745098 0.819607843137255 0.933333333333333 1" />
      </material>
    </visual>
    <collision>
      <origin
        xyz="0 0 0"
        rpy="0 0 0" />
      <geometry>
        <mesh
          filename="package://ball_balancer/meshes/table_arm_3_link.STL" />
      </geometry>
    </collision>
  </link>
  <joint
    name="table_arm_3_joint"
    type="revolute">
    <origin
      xyz="0.00455 0.039365 0"
      rpy="-0.2618 0 0" />
    <parent
      link="servo_arm_3_link" />
    <child
      link="table_arm_3_link" />
    <axis
      xyz="1 0 0" />
    <limit
      lower="-1.57"
      upper="0"
      effort="1.9"
      velocity="5.5" />
  </joint>
</robot>