<?xml version="1.0" encoding="utf-8"?>
<!-- This URDF was automatically created by SolidWorks to URDF Exporter! Originally created by Stephen Brawner (brawner@gmail.com) 
     Commit Version: 1.6.0-4-g7f85cfe  Build Version: 1.6.7995.38578
     For more information, please see http://wiki.ros.org/sw_urdf_exporter -->
<robot
  name="ball_balancer">
  <link
    name="base_link">
    <inertial>
      <origin
        xyz="-0.00098764643898577 0.000283424831778992 0.0127027628580996"
        rpy="0 0 0" />
      <mass
        value="0.140328552667325" />
      <inertia
        ixx="0.000337871673748816"
        ixy="-2.8151634803952E-06"
        ixz="-1.0335436792495E-06"
        iyy="0.00034127296506127"
        iyz="6.62368371674353E-07"
        izz="0.000598350452595104" />
    </inertial>
    <visual>
      <origin
        xyz="0 0 0"
        rpy="0 0 0" />
      <geometry>
        <mesh
          filename="package://ball_balancer/meshes/base_link.STL" />
      </geometry>
      <material
        name="">
        <color
          rgba="0.792156862745098 0.819607843137255 0.933333333333333 1" />
      </material>
    </visual>
    <collision>
      <origin
        xyz="0 0 0"
        rpy="0 0 0" />
      <geometry>
        <mesh
          filename="package://ball_balancer/meshes/base_link.STL" />
      </geometry>
    </collision>
  </link>
  <link
    name="servo_arm_1_link">
    <inertial>
      <origin
        xyz="3.67444957071446E-05 0.0141374705075089 -6.24500451351651E-17"
        rpy="0 0 0" />
      <mass
        value="0.00309980999161893" />
      <inertia
        ixx="7.53064525555482E-07"
        ixy="1.48615920681683E-22"
        ixz="2.83252122955225E-25"
        iyy="5.9755946353975E-08"
        iyz="-1.16769063089024E-21"
        izz="7.06064992829684E-07" />
    </inertial>
    <visual>
      <origin
        xyz="0 0 0"
        rpy="0 0 0" />
      <geometry>
        <mesh
          filename="package://ball_balancer/meshes/servo_arm_1_link.STL" />
      </geometry>
      <material
        name="">
        <color
          rgba="0.792156862745098 0.819607843137255 0.933333333333333 1" />
      </material>
    </visual>
    <collision>
      <origin
        xyz="0 0 0"
        rpy="0 0 0" />
      <geometry>
        <mesh
          filename="package://ball_balancer/meshes/servo_arm_1_link.STL" />
      </geometry>
    </collision>
  </link>
  <joint
    name="servo_arm_1_joint"
    type="revolute">
    <origin
      xyz="-0.065736 0.0073 0.03505"
      rpy="0 0 -1.5708" />
    <parent
      link="base_link" />
    <child
      link="servo_arm_1_link" />
    <axis
      xyz="-1 0 0" />
    <limit
      lower="-1.57"
      upper="0"
      effort="1.9"
      velocity="5.5" />
  </joint>
  <link
    name="table_arm_1_link">
    <inertial>
      <origin
        xyz="0.00200323165118161 -0.030245588924881 -1.18861464074027E-08"
        rpy="0 0 0" />
      <mass
        value="0.00256322375311019" />
      <inertia
        ixx="2.5397647409349E-07"
        ixy="2.24719540974155E-08"
        ixz="3.50562172645301E-14"
        iyy="3.10173137802653E-08"
        iyz="-3.73742597121492E-13"
        izz="2.47421754391359E-07" />
    </inertial>
    <visual>
      <origin
        xyz="0 0 0"
        rpy="0 0 0" />
      <geometry>
        <mesh
          filename="package://ball_balancer/meshes/table_arm_1_link.STL" />
      </geometry>
      <material
        name="">
        <color
          rgba="0.792156862745098 0.819607843137255 0.933333333333333 1" />
      </material>
    </visual>
    <collision>
      <origin
        xyz="0 0 0"
        rpy="0 0 0" />
      <geometry>
        <mesh
          filename="package://ball_balancer/meshes/table_arm_1_link.STL" />
      </geometry>
    </collision>
  </link>
  <joint
    name="table_arm_1_joint"
    type="revolute">
    <origin
      xyz="0.00455 0.039365 0"
      rpy="-0.2618 0 0" />
    <parent
      link="servo_arm_1_link" />
    <child
      link="table_arm_1_link" />
    <axis
      xyz="1 0 0" />
    <limit
      lower="-3.14"
      upper="0"
      effort="1.9"
      velocity="5.5" />
  </joint>
  <link
    name="table_arm_1_ball_link">
    <inertial>
      <origin
        xyz="-0.000746768348818531 0.0245456989225969 -1.18861463935249E-08"
        rpy="0 0 0" />
      <mass
        value="0.00256322375311019" />
      <inertia
        ixx="2.5397647409349E-07"
        ixy="2.24719540974154E-08"
        ixz="3.50562172651882E-14"
        iyy="3.10173137802652E-08"
        iyz="-3.73742597138036E-13"
        izz="2.47421754391359E-07" />
    </inertial>
    <visual>
      <origin
        xyz="0 0 0"
        rpy="0 0 0" />
      <geometry>
        <mesh
          filename="package://ball_balancer/meshes/table_arm_1_ball_link.STL" />
      </geometry>
      <material
        name="">
        <color
          rgba="0.792156862745098 0.819607843137255 0.933333333333333 1" />
      </material>
    </visual>
    <collision>
      <origin
        xyz="0 0 0"
        rpy="0 0 0" />
      <geometry>
        <mesh
          filename="package://ball_balancer/meshes/table_arm_1_ball_link.STL" />
      </geometry>
    </collision>
  </link>
  <joint
    name="table_arm_1_ball_joint"
    type="fixed">
    <origin
      xyz="0.00275 -0.054791 0"
      rpy="0 0 0" />
    <parent
      link="table_arm_1_link" />
    <child
      link="table_arm_1_ball_link" />
    <axis
      xyz="0 0 0" />
  </joint>
  <link
    name="servo_arm_2_link">
    <inertial>
      <origin
        xyz="3.67444957071542E-05 0.0141374705075089 -7.63278329429795E-17"
        rpy="0 0 0" />
      <mass
        value="0.00309980999161893" />
      <inertia
        ixx="7.53064525555482E-07"
        ixy="1.40620704134015E-22"
        ixz="5.43142717868586E-24"
        iyy="5.9755946353975E-08"
        iyz="-1.18099829620115E-21"
        izz="7.06064992829683E-07" />
    </inertial>
    <visual>
      <origin
        xyz="0 0 0"
        rpy="0 0 0" />
      <geometry>
        <mesh
          filename="package://ball_balancer/meshes/servo_arm_2_link.STL" />
      </geometry>
      <material
        name="">
        <color
          rgba="0.792156862745098 0.819607843137255 0.933333333333333 1" />
      </material>
    </visual>
    <collision>
      <origin
        xyz="0 0 0"
        rpy="0 0 0" />
      <geometry>
        <mesh
          filename="package://ball_balancer/meshes/servo_arm_2_link.STL" />
      </geometry>
    </collision>
  </link>
  <joint
    name="servo_arm_2_joint"
    type="revolute">
    <origin
      xyz="0.026546 -0.060579 0.03505"
      rpy="0 0 0.5236" />
    <parent
      link="base_link" />
    <child
      link="servo_arm_2_link" />
    <axis
      xyz="-1 0 0" />
    <limit
      lower="-1.57"
      upper="0"
      effort="1.9"
      velocity="5.5" />
  </joint>
  <link
    name="table_arm_2_link">
    <inertial>
      <origin
        xyz="0.00200322355127836 -0.0302455797787152 -9.30981117544527E-09"
        rpy="0 0 0" />
      <mass
        value="0.00256321394494201" />
      <inertia
        ixx="2.53975403411485E-07"
        ixy="2.2471697435682E-08"
        ixz="4.96634103249932E-14"
        iyy="3.10172591631405E-08"
        iyz="-2.96520786613035E-13"
        izz="2.4742054926573E-07" />
    </inertial>
    <visual>
      <origin
        xyz="0 0 0"
        rpy="0 0 0" />
      <geometry>
        <mesh
          filename="package://ball_balancer/meshes/table_arm_2_link.STL" />
      </geometry>
      <material
        name="">
        <color
          rgba="0.792156862745098 0.819607843137255 0.933333333333333 1" />
      </material>
    </visual>
    <collision>
      <origin
        xyz="0 0 0"
        rpy="0 0 0" />
      <geometry>
        <mesh
          filename="package://ball_balancer/meshes/table_arm_2_link.STL" />
      </geometry>
    </collision>
  </link>
  <joint
    name="table_arm_2_joint"
    type="revolute">
    <origin
      xyz="0.00455 0.039365 0"
      rpy="-0.27925 0 0" />
    <parent
      link="servo_arm_2_link" />
    <child
      link="table_arm_2_link" />
    <axis
      xyz="1 0 0" />
    <limit
      lower="-3.14"
      upper="0"
      effort="1.9"
      velocity="5.5" />
  </joint>
  <link
    name="table_arm_2_ball_link">
    <inertial>
      <origin
        xyz="-0.000746776448721724 0.0245457080687627 -9.30981114422025E-09"
        rpy="0 0 0" />
      <mass
        value="0.00256321394494201" />
      <inertia
        ixx="2.53975403411485E-07"
        ixy="2.2471697435682E-08"
        ixz="4.96634103249932E-14"
        iyy="3.10172591631405E-08"
        iyz="-2.96520786613035E-13"
        izz="2.4742054926573E-07" />
    </inertial>
    <visual>
      <origin
        xyz="0 0 0"
        rpy="0 0 0" />
      <geometry>
        <mesh
          filename="package://ball_balancer/meshes/table_arm_2_ball_link.STL" />
      </geometry>
      <material
        name="">
        <color
          rgba="0.792156862745098 0.819607843137255 0.933333333333333 1" />
      </material>
    </visual>
    <collision>
      <origin
        xyz="0 0 0"
        rpy="0 0 0" />
      <geometry>
        <mesh
          filename="package://ball_balancer/meshes/table_arm_2_ball_link.STL" />
      </geometry>
    </collision>
  </link>
  <joint
    name="table_arm_2_ball_joint"
    type="fixed">
    <origin
      xyz="0.00275 -0.054791 0"
      rpy="0 0 0" />
    <parent
      link="table_arm_2_link" />
    <child
      link="table_arm_2_ball_link" />
    <axis
      xyz="0 0 0" />
  </joint>
  <link
    name="servo_arm_3_link">
    <inertial>
      <origin
        xyz="3.67444957071576E-05 0.0141374705075089 -7.63278329429795E-17"
        rpy="0 0 0" />
      <mass
        value="0.00309980999161893" />
      <inertia
        ixx="7.53064525555483E-07"
        ixy="-6.61744490042422E-24"
        ixz="1.01266360720706E-24"
        iyy="5.9755946353975E-08"
        iyz="-1.08115405423308E-21"
        izz="7.06064992829684E-07" />
    </inertial>
    <visual>
      <origin
        xyz="0 0 0"
        rpy="0 0 0" />
      <geometry>
        <mesh
          filename="package://ball_balancer/meshes/servo_arm_3_link.STL" />
      </geometry>
      <material
        name="">
        <color
          rgba="0.792156862745098 0.819607843137255 0.933333333333333 1" />
      </material>
    </visual>
    <collision>
      <origin
        xyz="0 0 0"
        rpy="0 0 0" />
      <geometry>
        <mesh
          filename="package://ball_balancer/meshes/servo_arm_3_link.STL" />
      </geometry>
    </collision>
  </link>
  <joint
    name="servo_arm_3_joint"
    type="revolute">
    <origin
      xyz="0.03919 0.053279 0.03505"
      rpy="0 0 2.618" />
    <parent
      link="base_link" />
    <child
      link="servo_arm_3_link" />
    <axis
      xyz="-1 0 0" />
    <limit
      lower="-1.57"
      upper="0"
      effort="1.9"
      velocity="5.5" />
  </joint>
  <link
    name="table_arm_3_link">
    <inertial>
      <origin
        xyz="0.00200321195554552 -0.0302455620616148 -1.03093975925561E-08"
        rpy="0 0 0" />
      <mass
        value="0.00256319746004798" />
      <inertia
        ixx="2.53973519433809E-07"
        ixy="2.24713070970572E-08"
        ixz="1.27314190247887E-13"
        iyy="3.10171931225822E-08"
        iyz="-3.13248110057503E-13"
        izz="2.47418505658137E-07" />
    </inertial>
    <visual>
      <origin
        xyz="0 0 0"
        rpy="0 0 0" />
      <geometry>
        <mesh
          filename="package://ball_balancer/meshes/table_arm_3_link.STL" />
      </geometry>
      <material
        name="">
        <color
          rgba="0.792156862745098 0.819607843137255 0.933333333333333 1" />
      </material>
    </visual>
    <collision>
      <origin
        xyz="0 0 0"
        rpy="0 0 0" />
      <geometry>
        <mesh
          filename="package://ball_balancer/meshes/table_arm_3_link.STL" />
      </geometry>
    </collision>
  </link>
  <joint
    name="table_arm_3_joint"
    type="revolute">
    <origin
      xyz="0.00455 0.039365 0"
      rpy="-0.2618 0 0" />
    <parent
      link="servo_arm_3_link" />
    <child
      link="table_arm_3_link" />
    <axis
      xyz="1 0 0" />
    <limit
      lower="-3.14"
      upper="0"
      effort="1.9"
      velocity="5.5" />
  </joint>
  <link
    name="table_arm_3_ball_link">
    <inertial>
      <origin
        xyz="-0.000746788044454532 0.0245457257858631 -1.03093975578616E-08"
        rpy="0 0 0" />
      <mass
        value="0.00256319746004798" />
      <inertia
        ixx="2.53973519433809E-07"
        ixy="2.24713070970572E-08"
        ixz="1.27314190251196E-13"
        iyy="3.10171931225822E-08"
        iyz="-3.13248110055848E-13"
        izz="2.47418505658137E-07" />
    </inertial>
    <visual>
      <origin
        xyz="0 0 0"
        rpy="0 0 0" />
      <geometry>
        <mesh
          filename="package://ball_balancer/meshes/table_arm_3_ball_link.STL" />
      </geometry>
      <material
        name="">
        <color
          rgba="0.792156862745098 0.819607843137255 0.933333333333333 1" />
      </material>
    </visual>
    <collision>
      <origin
        xyz="0 0 0"
        rpy="0 0 0" />
      <geometry>
        <mesh
          filename="package://ball_balancer/meshes/table_arm_3_ball_link.STL" />
      </geometry>
    </collision>
  </link>
  <joint
    name="table_arm_3_ball_joint"
    type="fixed">
    <origin
      xyz="0.00275 -0.054791 0"
      rpy="0 0 0" />
    <parent
      link="table_arm_3_link" />
    <child
      link="table_arm_3_ball_link" />
    <axis
      xyz="0 0 0" />
  </joint>
</robot>