<?xml version="1.0" encoding="utf-8"?>
<!-- This URDF was automatically created by SolidWorks to URDF Exporter! Originally created by Stephen Brawner (brawner@gmail.com) 
     Commit Version: 1.6.0-4-g7f85cfe  Build Version: 1.6.7995.38578
     For more information, please see http://wiki.ros.org/sw_urdf_exporter -->
<robot
  name="ball_balancer2">
  <link
    name="base_link">
    <inertial>
      <origin
        xyz="-0.00015538 0.039405 0.00054565"
        rpy="0 0 0" />
      <mass
        value="0.25395" />
      <inertia
        ixx="0.00052253"
        ixy="-1.5515E-06"
        ixz="-2.7765E-06"
        iyy="0.00059627"
        iyz="4.2751E-06"
        izz="0.00051908" />
    </inertial>
    <visual>
      <origin
        xyz="0 0 0"
        rpy="0 0 0" />
      <geometry>
        <mesh
          filename="package://ball_balancer2/meshes/base_link.STL" />
      </geometry>
      <material
        name="">
        <color
          rgba="0.79216 0.81961 0.93333 1" />
      </material>
    </visual>
    <collision>
      <origin
        xyz="0 0 0"
        rpy="0 0 0" />
      <geometry>
        <mesh
          filename="package://ball_balancer2/meshes/base_link.STL" />
      </geometry>
    </collision>
  </link>
  <link
    name="servo_arm_1">
    <inertial>
      <origin
        xyz="3.6744E-05 0.014137 -6.245E-17"
        rpy="0 0 0" />
      <mass
        value="0.0030998" />
      <inertia
        ixx="7.5306E-07"
        ixy="1.4846E-22"
        ixz="2.8325E-25"
        iyy="5.9756E-08"
        iyz="-1.1677E-21"
        izz="7.0606E-07" />
    </inertial>
    <visual>
      <origin
        xyz="0 0 0"
        rpy="0 0 0" />
      <geometry>
        <mesh
          filename="package://ball_balancer2/meshes/servo_arm_1.STL" />
      </geometry>
      <material
        name="">
        <color
          rgba="0.79216 0.81961 0.93333 1" />
      </material>
    </visual>
    <collision>
      <origin
        xyz="0 0 0"
        rpy="0 0 0" />
      <geometry>
        <mesh
          filename="package://ball_balancer2/meshes/servo_arm_1.STL" />
      </geometry>
    </collision>
  </link>
  <joint
    name="servo_arm_1_revolute"
    type="revolute">
    <origin
      xyz="-0.0073 -0.065736 0.03755"
      rpy="0 0 0" />
    <parent
      link="base_link" />
    <child
      link="servo_arm_1" />
    <axis
      xyz="-1 0 0" />
    <limit
      lower="-1.57"
      upper="0"
      effort="1.9"
      velocity="5.5" />
  </joint>
  <link
    name="table_arm_1">
    <inertial>
      <origin
        xyz="0.0020032 -0.030246 -1.1886E-08"
        rpy="0 0 0" />
      <mass
        value="0.0025632" />
      <inertia
        ixx="2.5398E-07"
        ixy="2.2472E-08"
        ixz="3.5056E-14"
        iyy="3.1017E-08"
        iyz="-3.7374E-13"
        izz="2.4742E-07" />
    </inertial>
    <visual>
      <origin
        xyz="0 0 0"
        rpy="0 0 0" />
      <geometry>
        <mesh
          filename="package://ball_balancer2/meshes/table_arm_1.STL" />
      </geometry>
      <material
        name="">
        <color
          rgba="0.79216 0.81961 0.93333 1" />
      </material>
    </visual>
    <collision>
      <origin
        xyz="0 0 0"
        rpy="0 0 0" />
      <geometry>
        <mesh
          filename="package://ball_balancer2/meshes/table_arm_1.STL" />
      </geometry>
    </collision>
  </link>
  <joint
    name="table_arm_1_revolute"
    type="revolute">
    <origin
      xyz="0.00455 0.039365 0"
      rpy="-0.47144 0 0" />
    <parent
      link="servo_arm_1" />
    <child
      link="table_arm_1" />
    <axis
      xyz="1 0 0" />
    <limit
      lower="-3.14"
      upper="0"
      effort="1.9"
      velocity="5.5" />
  </joint>
  <link name="table_arm_1_ball" />
  <joint
    name="table_arm_1_ball_joint"
    type="fixed">
    <origin
      xyz="0.00275 -0.054583 0"
      rpy="0 0 0" />
    <parent
      link="table_arm_1" />
    <child
      link="table_arm_1_ball" />
    <axis
      xyz="0 0 0" />
  </joint>
  <link
    name="servo_arm_2">
    <inertial>
      <origin
        xyz="3.67444957071403E-05 0.0141374705075078 -2.06779038336435E-15"
        rpy="0 0 0" />
      <mass
        value="0.00309980999161893" />
      <inertia
        ixx="7.53064525555482E-07"
        ixy="2.15066959263787E-23"
        ixz="9.0989867380833E-24"
        iyy="5.9755946353975E-08"
        iyz="-1.34292772447984E-21"
        izz="7.06064992829684E-07" />
    </inertial>
    <visual>
      <origin
        xyz="0 0 0"
        rpy="0 0 0" />
      <geometry>
        <mesh
          filename="package://ball_balancer2/meshes/servo_arm_2.STL" />
      </geometry>
      <material
        name="">
        <color
          rgba="0.792156862745098 0.819607843137255 0.933333333333333 1" />
      </material>
    </visual>
    <collision>
      <origin
        xyz="0 0 0"
        rpy="0 0 0" />
      <geometry>
        <mesh
          filename="package://ball_balancer2/meshes/servo_arm_2.STL" />
      </geometry>
    </collision>
  </link>
  <joint
    name="servo_arm_2_revolute"
    type="revolute">
    <origin
      xyz="0.060579 0.026546 0.03755"
      rpy="-0.010265 0 2.0944" />
    <parent
      link="base_link" />
    <child
      link="servo_arm_2" />
    <axis
      xyz="-1 0 0" />
    <limit
      lower="-1.57"
      upper="0"
      effort="1.9"
      velocity="5.5" />
  </joint>
  <link
    name="table_arm_2">
    <inertial>
      <origin
        xyz="0.00200322317368745 -0.0302455787102662 -7.30162207432383E-09"
        rpy="0 0 0" />
      <mass
        value="0.00256321315526102" />
      <inertia
        ixx="2.53975309310461E-07"
        ixy="2.24716883099034E-08"
        ixz="3.38452589465274E-14"
        iyy="3.1017255098745E-08"
        iyz="-2.38983580560879E-13"
        izz="2.47420430501569E-07" />
    </inertial>
    <visual>
      <origin
        xyz="0 0 0"
        rpy="0 0 0" />
      <geometry>
        <mesh
          filename="package://ball_balancer2/meshes/table_arm_2.STL" />
      </geometry>
      <material
        name="">
        <color
          rgba="0.792156862745098 0.819607843137255 0.933333333333333 1" />
      </material>
    </visual>
    <collision>
      <origin
        xyz="0 0 0"
        rpy="0 0 0" />
      <geometry>
        <mesh
          filename="package://ball_balancer2/meshes/table_arm_2.STL" />
      </geometry>
    </collision>
  </link>
  <joint
    name="table_arm_2_revolute"
    type="revolute">
    <origin
      xyz="0.00455 0.039365 0"
      rpy="-0.46126 0 0" />
    <parent
      link="servo_arm_2" />
    <child
      link="table_arm_2" />
    <axis
      xyz="1 0 0" />
    <limit
      lower="-3.14"
      upper="0"
      effort="1.9"
      velocity="5.5" />
  </joint>
  <link name="table_arm_2_ball" />
  <joint
    name="table_arm_2_ball_joint"
    type="fixed">
    <origin
      xyz="0.00275 -0.054583 0"
      rpy="0 0 0" />
    <parent
      link="table_arm_2" />
    <child
      link="table_arm_2_ball" />
    <axis
      xyz="0 0 0" />
  </joint>
  <link
    name="servo_arm_3">
    <inertial>
      <origin
        xyz="0 0 0"
        rpy="0 0 0" />
      <mass
        value="0" />
      <inertia
        ixx="0"
        ixy="0"
        ixz="0"
        iyy="0"
        iyz="0"
        izz="0" />
    </inertial>
    <visual>
      <origin
        xyz="0 0 0"
        rpy="0 0 0" />
      <geometry>
        <mesh
          filename="package://ball_balancer2/meshes/servo_arm_3.STL" />
      </geometry>
      <material
        name="">
        <color
          rgba="1 1 1 1" />
      </material>
    </visual>
    <collision>
      <origin
        xyz="0 0 0"
        rpy="0 0 0" />
      <geometry>
        <mesh
          filename="package://ball_balancer2/meshes/servo_arm_3.STL" />
      </geometry>
    </collision>
  </link>
  <joint
    name="servo_arm_3_revolute"
    type="revolute">
    <origin
      xyz="-0.053279 0.03919 0.03755"
      rpy="-0.010265 0 -2.0944" />
    <parent
      link="base_link" />
    <child
      link="servo_arm_3" />
    <axis
      xyz="-1 0 0" />
    <limit
      lower="-1.57"
      upper="0"
      effort="1.9"
      velocity="5.5" />
  </joint>
  <link
    name="table_arm_3">
    <inertial>
      <origin
        xyz="0.00200321165845766 -0.0302455610368241 -7.73754285990358E-09"
        rpy="0 0 0" />
      <mass
        value="0.00256319659543894" />
      <inertia
        ixx="2.53973421781188E-07"
        ixy="2.24712999182535E-08"
        ixz="1.10207121719404E-13"
        iyy="3.10171892862842E-08"
        iyz="-2.43362774805972E-13"
        izz="2.47418381574632E-07" />
    </inertial>
    <visual>
      <origin
        xyz="0 0 0"
        rpy="0 0 0" />
      <geometry>
        <mesh
          filename="package://ball_balancer2/meshes/table_arm_3.STL" />
      </geometry>
      <material
        name="">
        <color
          rgba="0.792156862745098 0.819607843137255 0.933333333333333 1" />
      </material>
    </visual>
    <collision>
      <origin
        xyz="0 0 0"
        rpy="0 0 0" />
      <geometry>
        <mesh
          filename="package://ball_balancer2/meshes/table_arm_3.STL" />
      </geometry>
    </collision>
  </link>
  <joint
    name="table_arm_3_revolute"
    type="revolute">
    <origin
      xyz="0.00455 0.039365 0"
      rpy="-0.46126 0 0" />
    <parent
      link="servo_arm_3" />
    <child
      link="table_arm_3" />
    <axis
      xyz="1 0 0" />
    <limit
      lower="-3.14"
      upper="0"
      effort="1.9"
      velocity="5.5" />
  </joint>
  <link name="table_arm_3_ball" />
  <joint
    name="table_arm_3_ball_joint"
    type="fixed">
    <origin
      xyz="0.00275 -0.054583 0"
      rpy="0 0 0" />
    <parent
      link="table_arm_3" />
    <child
      link="table_arm_3_ball" />
    <axis
      xyz="0 0 0" />
  </joint>
</robot>